2025-06-08 21:17:39,487 - INFO - \u2705 \u0411\u043e\u0442 \u0437\u0430\u043f\u0443\u0449\u0435\u043d\u043e
2025-06-08 21:17:39,851 - INFO - Scheduler started
2025-06-08 21:17:39,851 - INFO - Application started
2025-06-08 21:22:24,935 - INFO - \u2705 \u0411\u043e\u0442 \u0437\u0430\u043f\u0443\u0449\u0435\u043d\u043e
2025-06-08 21:22:25,354 - INFO - Scheduler started
2025-06-08 21:22:25,354 - INFO - Application started
2025-06-08 21:22:48,224 - INFO - ✅ Бот запущено
2025-06-08 21:22:48,539 - INFO - Scheduler started
2025-06-08 21:22:48,540 - INFO - Application started
2025-06-08 21:23:04,206 - INFO - ✅ Бот запущено
2025-06-08 21:23:04,552 - INFO - Scheduler started
2025-06-08 21:23:04,552 - INFO - Application started
2025-06-08 21:23:37,094 - INFO - ✅ Бот запущено
2025-06-08 21:23:37,426 - INFO - Scheduler started
2025-06-08 21:23:37,426 - INFO - Application started
2025-06-08 21:23:56,618 - INFO - ✅ Бот запущено
2025-06-08 21:23:56,943 - INFO - Scheduler started
2025-06-08 21:23:56,943 - INFO - Application started
2025-06-08 21:34:56,047 - INFO - ✅ Бот запущено
2025-06-08 21:34:56,891 - INFO - Scheduler started
2025-06-08 21:34:56,892 - INFO - Application started
2025-06-08 21:35:17,129 - INFO - ✅ Бот запущено
2025-06-08 21:35:17,468 - INFO - Scheduler started
2025-06-08 21:35:17,468 - INFO - Application started
2025-06-08 21:35:28,180 - INFO - ✅ Бот запущено
2025-06-08 21:35:28,520 - INFO - Scheduler started
2025-06-08 21:35:28,520 - INFO - Application started
2025-06-08 21:35:36,608 - INFO - ✅ Бот запущено
2025-06-08 21:35:36,935 - INFO - Scheduler started
2025-06-08 21:35:36,936 - INFO - Application started
2025-06-08 21:36:23,276 - INFO - ✅ Бот запущено
2025-06-08 21:36:23,630 - INFO - Scheduler started
2025-06-08 21:36:23,630 - INFO - Application started
2025-06-08 21:38:55,543 - INFO - ✅ Бот запущено
2025-06-08 21:38:56,205 - INFO - Scheduler started
2025-06-08 21:38:56,205 - INFO - Application started
2025-06-08 21:39:40,907 - INFO - ✅ Бот запущено
2025-06-08 21:39:41,297 - INFO - Scheduler started
2025-06-08 21:39:41,298 - INFO - Application started
2025-06-11 10:40:30,068 - INFO - ✅ Бот запущено
2025-06-11 10:40:30,968 - INFO - Scheduler started
2025-06-11 10:40:30,968 - INFO - Application started
Traceback (most recent call last):
  File "D:\KonradDrive\Crypto_Way\Trade_bots\pairhelper\main.py", line 18, in <module>
    from handlers.pairs import (
        start_pair_removal, handle_pair_selection, SELECTING
    )
  File "D:\KonradDrive\Crypto_Way\Trade_bots\pairhelper\handlers\pairs.py", line 3, in <module>
    from services.pair_storage import get_all_pairs, delete_pair_by_id
ImportError: cannot import name 'get_all_pairs' from 'services.pair_storage' (D:\KonradDrive\Crypto_Way\Trade_bots\pairhelper\services\pair_storage.py)
D:\KonradDrive\Crypto_Way\Trade_bots\pairhelper\main.py:69: PTBUserWarning: If 'per_message=False', 'CallbackQueryHandler' will not be tracked for every message. Read this FAQ entry to learn more about the per_* settings: https://github.com/python-telegram-bot/python-telegram-bot/wiki/Frequently-Asked-Questions#what-do-the-per_-settings-in-conversationhandler-do.
  remove_pairs_scene = ConversationHandler(
2025-06-11 12:22:00,117 - INFO - ✅ Бот запущено
2025-06-11 12:22:00,497 - INFO - Scheduler started
2025-06-11 12:22:00,498 - INFO - Application started
2025-06-11 12:22:00,717 - ERROR - No error handlers are registered, logging exception.
Traceback (most recent call last):
  File "C:\Users\HP\AppData\Local\Programs\Python\Python313\Lib\site-packages\telegram\ext\_application.py", line 1298, in process_update
    await coroutine
  File "C:\Users\HP\AppData\Local\Programs\Python\Python313\Lib\site-packages\telegram\ext\_handlers\conversationhandler.py", line 842, in handle_update
    new_state: object = await handler.handle_update(
                        ^^^^^^^^^^^^^^^^^^^^^^^^^^^^
        update, application, handler_check_result, context
        ^^^^^^^^^^^^^^^^^^^^^^^^^^^^^^^^^^^^^^^^^^^^^^^^^^
    )
    ^
  File "C:\Users\HP\AppData\Local\Programs\Python\Python313\Lib\site-packages\telegram\ext\_handlers\basehandler.py", line 158, in handle_update
    return await self.callback(update, context)
           ^^^^^^^^^^^^^^^^^^^^^^^^^^^^^^^^^^^^
  File "D:\KonradDrive\Crypto_Way\Trade_bots\pairhelper\handlers\pairs.py", line 31, in start_pair_removal
    markup = build_pair_selection_keyboard(pairs)
  File "D:\KonradDrive\Crypto_Way\Trade_bots\pairhelper\handlers\pairs.py", line 11, in build_pair_selection_keyboard
    for pair_id, token_a, token_b, _ in pairs:
        ^^^^^^^^^^^^^^^^^^^^^^^^^^^^
ValueError: too many values to unpack (expected 4)
D:\KonradDrive\Crypto_Way\Trade_bots\pairhelper\main.py:69: PTBUserWarning: If 'per_message=False', 'CallbackQueryHandler' will not be tracked for every message. Read this FAQ entry to learn more about the per_* settings: https://github.com/python-telegram-bot/python-telegram-bot/wiki/Frequently-Asked-Questions#what-do-the-per_-settings-in-conversationhandler-do.
  remove_pairs_scene = ConversationHandler(
2025-06-11 12:22:06,580 - INFO - ✅ Бот запущено
2025-06-11 12:22:06,910 - INFO - Scheduler started
2025-06-11 12:22:06,910 - INFO - Application started
2025-06-11 12:22:50,592 - ERROR - No error handlers are registered, logging exception.
Traceback (most recent call last):
  File "C:\Users\HP\AppData\Local\Programs\Python\Python313\Lib\site-packages\telegram\ext\_application.py", line 1298, in process_update
    await coroutine
  File "C:\Users\HP\AppData\Local\Programs\Python\Python313\Lib\site-packages\telegram\ext\_handlers\conversationhandler.py", line 842, in handle_update
    new_state: object = await handler.handle_update(
                        ^^^^^^^^^^^^^^^^^^^^^^^^^^^^
        update, application, handler_check_result, context
        ^^^^^^^^^^^^^^^^^^^^^^^^^^^^^^^^^^^^^^^^^^^^^^^^^^
    )
    ^
  File "C:\Users\HP\AppData\Local\Programs\Python\Python313\Lib\site-packages\telegram\ext\_handlers\basehandler.py", line 158, in handle_update
    return await self.callback(update, context)
           ^^^^^^^^^^^^^^^^^^^^^^^^^^^^^^^^^^^^
  File "D:\KonradDrive\Crypto_Way\Trade_bots\pairhelper\handlers\pairs.py", line 31, in start_pair_removal
    markup = build_pair_selection_keyboard(pairs)
  File "D:\KonradDrive\Crypto_Way\Trade_bots\pairhelper\handlers\pairs.py", line 11, in build_pair_selection_keyboard
    for pair_id, token_a, token_b, _ in pairs:
        ^^^^^^^^^^^^^^^^^^^^^^^^^^^^
ValueError: too many values to unpack (expected 4)
2025-06-11 12:23:48,927 - ERROR - No error handlers are registered, logging exception.
Traceback (most recent call last):
  File "C:\Users\HP\AppData\Local\Programs\Python\Python313\Lib\site-packages\telegram\ext\_application.py", line 1298, in process_update
    await coroutine
  File "C:\Users\HP\AppData\Local\Programs\Python\Python313\Lib\site-packages\telegram\ext\_handlers\conversationhandler.py", line 842, in handle_update
    new_state: object = await handler.handle_update(
                        ^^^^^^^^^^^^^^^^^^^^^^^^^^^^
        update, application, handler_check_result, context
        ^^^^^^^^^^^^^^^^^^^^^^^^^^^^^^^^^^^^^^^^^^^^^^^^^^
    )
    ^
  File "C:\Users\HP\AppData\Local\Programs\Python\Python313\Lib\site-packages\telegram\ext\_handlers\basehandler.py", line 158, in handle_update
    return await self.callback(update, context)
           ^^^^^^^^^^^^^^^^^^^^^^^^^^^^^^^^^^^^
  File "D:\KonradDrive\Crypto_Way\Trade_bots\pairhelper\handlers\pairs.py", line 31, in start_pair_removal
    markup = build_pair_selection_keyboard(pairs)
  File "D:\KonradDrive\Crypto_Way\Trade_bots\pairhelper\handlers\pairs.py", line 11, in build_pair_selection_keyboard
    for pair_id, token_a, token_b, _ in pairs:
        ^^^^^^^^^^^^^^^^^^^^^^^^^^^^
ValueError: too many values to unpack (expected 4)
Traceback (most recent call last):
  File "D:\KonradDrive\Crypto_Way\Trade_bots\pairhelper\main.py", line 69, in <module>
    remove_pairs_scene = ConversationHandler(
        eentry_points=[MessageHandler(filters.Regex("\u041c\u043e\u0457 \u043f\u0430\u0440\u0438"), start_pair_removal)],
    ...<3 lines>...
        fallbacks=[],
    )
TypeError: ConversationHandler.__init__() got an unexpected keyword argument 'eentry_points'. Did you mean 'entry_points'?
Traceback (most recent call last):
  File "D:\KonradDrive\Crypto_Way\Trade_bots\pairhelper\main.py", line 69, in <module>
    remove_pairs_scene = ConversationHandler(
        eentry_points=[MessageHandler(filters.Regex("\u041c\u043e\u0457 \u043f\u0430\u0440\u0438"), start_pair_removal)],
    ...<3 lines>...
        fallbacks=[],
    )
TypeError: ConversationHandler.__init__() got an unexpected keyword argument 'eentry_points'. Did you mean 'entry_points'?
D:\KonradDrive\Crypto_Way\Trade_bots\pairhelper\main.py:69: PTBUserWarning: If 'per_message=False', 'CallbackQueryHandler' will not be tracked for every message. Read this FAQ entry to learn more about the per_* settings: https://github.com/python-telegram-bot/python-telegram-bot/wiki/Frequently-Asked-Questions#what-do-the-per_-settings-in-conversationhandler-do.
  remove_pairs_scene = ConversationHandler(
2025-06-11 12:27:45,176 - INFO - ✅ Бот запущено
2025-06-11 12:27:45,619 - INFO - Scheduler started
2025-06-11 12:27:45,620 - INFO - Application started
2025-06-11 12:27:45,768 - ERROR - No error handlers are registered, logging exception.
Traceback (most recent call last):
  File "C:\Users\HP\AppData\Local\Programs\Python\Python313\Lib\site-packages\telegram\ext\_application.py", line 1298, in process_update
    await coroutine
  File "C:\Users\HP\AppData\Local\Programs\Python\Python313\Lib\site-packages\telegram\ext\_handlers\conversationhandler.py", line 842, in handle_update
    new_state: object = await handler.handle_update(
                        ^^^^^^^^^^^^^^^^^^^^^^^^^^^^
        update, application, handler_check_result, context
        ^^^^^^^^^^^^^^^^^^^^^^^^^^^^^^^^^^^^^^^^^^^^^^^^^^
    )
    ^
  File "C:\Users\HP\AppData\Local\Programs\Python\Python313\Lib\site-packages\telegram\ext\_handlers\basehandler.py", line 158, in handle_update
    return await self.callback(update, context)
           ^^^^^^^^^^^^^^^^^^^^^^^^^^^^^^^^^^^^
  File "D:\KonradDrive\Crypto_Way\Trade_bots\pairhelper\handlers\pairs.py", line 31, in start_pair_removal
    markup = build_pair_selection_keyboard(pairs)
  File "D:\KonradDrive\Crypto_Way\Trade_bots\pairhelper\handlers\pairs.py", line 11, in build_pair_selection_keyboard
    for pair_id, token_a, token_b, _ in pairs:
        ^^^^^^^^^^^^^^^^^^^^^^^^^^^^
ValueError: too many values to unpack (expected 4)
2025-06-11 12:27:45,814 - ERROR - No error handlers are registered, logging exception.
Traceback (most recent call last):
  File "C:\Users\HP\AppData\Local\Programs\Python\Python313\Lib\site-packages\telegram\ext\_application.py", line 1298, in process_update
    await coroutine
  File "C:\Users\HP\AppData\Local\Programs\Python\Python313\Lib\site-packages\telegram\ext\_handlers\conversationhandler.py", line 842, in handle_update
    new_state: object = await handler.handle_update(
                        ^^^^^^^^^^^^^^^^^^^^^^^^^^^^
        update, application, handler_check_result, context
        ^^^^^^^^^^^^^^^^^^^^^^^^^^^^^^^^^^^^^^^^^^^^^^^^^^
    )
    ^
  File "C:\Users\HP\AppData\Local\Programs\Python\Python313\Lib\site-packages\telegram\ext\_handlers\basehandler.py", line 158, in handle_update
    return await self.callback(update, context)
           ^^^^^^^^^^^^^^^^^^^^^^^^^^^^^^^^^^^^
  File "D:\KonradDrive\Crypto_Way\Trade_bots\pairhelper\handlers\pairs.py", line 31, in start_pair_removal
    markup = build_pair_selection_keyboard(pairs)
  File "D:\KonradDrive\Crypto_Way\Trade_bots\pairhelper\handlers\pairs.py", line 11, in build_pair_selection_keyboard
    for pair_id, token_a, token_b, _ in pairs:
        ^^^^^^^^^^^^^^^^^^^^^^^^^^^^
ValueError: too many values to unpack (expected 4)
D:\KonradDrive\Crypto_Way\Trade_bots\pairhelper\main.py:69: PTBUserWarning: If 'per_message=False', 'CallbackQueryHandler' will not be tracked for every message. Read this FAQ entry to learn more about the per_* settings: https://github.com/python-telegram-bot/python-telegram-bot/wiki/Frequently-Asked-Questions#what-do-the-per_-settings-in-conversationhandler-do.
  remove_pairs_scene = ConversationHandler(
2025-06-11 12:28:39,596 - INFO - ✅ Бот запущено
2025-06-11 12:28:39,910 - INFO - Scheduler started
2025-06-11 12:28:39,911 - INFO - Application started
D:\KonradDrive\Crypto_Way\Trade_bots\pairhelper\main.py:69: PTBUserWarning: If 'per_message=False', 'CallbackQueryHandler' will not be tracked for every message. Read this FAQ entry to learn more about the per_* settings: https://github.com/python-telegram-bot/python-telegram-bot/wiki/Frequently-Asked-Questions#what-do-the-per_-settings-in-conversationhandler-do.
  remove_pairs_scene = ConversationHandler(
2025-06-11 12:28:47,601 - INFO - ✅ Бот запущено
2025-06-11 12:28:47,925 - INFO - Scheduler started
2025-06-11 12:28:47,925 - INFO - Application started
D:\KonradDrive\Crypto_Way\Trade_bots\pairhelper\main.py:69: PTBUserWarning: If 'per_message=False', 'CallbackQueryHandler' will not be tracked for every message. Read this FAQ entry to learn more about the per_* settings: https://github.com/python-telegram-bot/python-telegram-bot/wiki/Frequently-Asked-Questions#what-do-the-per_-settings-in-conversationhandler-do.
  remove_pairs_scene = ConversationHandler(
2025-06-11 12:29:35,848 - INFO - ✅ Бот запущено
2025-06-11 12:29:36,158 - INFO - Scheduler started
2025-06-11 12:29:36,158 - INFO - Application started
D:\KonradDrive\Crypto_Way\Trade_bots\pairhelper\main.py:69: PTBUserWarning: If 'per_message=False', 'CallbackQueryHandler' will not be tracked for every message. Read this FAQ entry to learn more about the per_* settings: https://github.com/python-telegram-bot/python-telegram-bot/wiki/Frequently-Asked-Questions#what-do-the-per_-settings-in-conversationhandler-do.
  remove_pairs_scene = ConversationHandler(
2025-06-11 12:34:21,368 - INFO - ✅ Бот запущено
2025-06-11 12:34:21,792 - INFO - Scheduler started
2025-06-11 12:34:21,793 - INFO - Application started
2025-06-11 12:34:36,719 - ERROR - No error handlers are registered, logging exception.
Traceback (most recent call last):
  File "C:\Users\HP\AppData\Local\Programs\Python\Python313\Lib\site-packages\telegram\ext\_application.py", line 1298, in process_update
    await coroutine
  File "C:\Users\HP\AppData\Local\Programs\Python\Python313\Lib\site-packages\telegram\ext\_handlers\conversationhandler.py", line 842, in handle_update
    new_state: object = await handler.handle_update(
                        ^^^^^^^^^^^^^^^^^^^^^^^^^^^^
        update, application, handler_check_result, context
        ^^^^^^^^^^^^^^^^^^^^^^^^^^^^^^^^^^^^^^^^^^^^^^^^^^
    )
    ^
  File "C:\Users\HP\AppData\Local\Programs\Python\Python313\Lib\site-packages\telegram\ext\_handlers\basehandler.py", line 158, in handle_update
    return await self.callback(update, context)
           ^^^^^^^^^^^^^^^^^^^^^^^^^^^^^^^^^^^^
  File "D:\KonradDrive\Crypto_Way\Trade_bots\pairhelper\handlers\pairs.py", line 31, in start_pair_removal
    markup = build_pair_selection_keyboard(pairs)
  File "D:\KonradDrive\Crypto_Way\Trade_bots\pairhelper\handlers\pairs.py", line 11, in build_pair_selection_keyboard
    for pair_id, token_a, token_b, _ in pairs:
        ^^^^^^^^^^^^^^^^^^^^^^^^^^^^
ValueError: too many values to unpack (expected 4)
D:\KonradDrive\Crypto_Way\Trade_bots\pairhelper\main.py:69: PTBUserWarning: If 'per_message=False', 'CallbackQueryHandler' will not be tracked for every message. Read this FAQ entry to learn more about the per_* settings: https://github.com/python-telegram-bot/python-telegram-bot/wiki/Frequently-Asked-Questions#what-do-the-per_-settings-in-conversationhandler-do.
  remove_pairs_scene = ConversationHandler(
2025-06-11 12:34:45,205 - INFO - ✅ Бот запущено
2025-06-11 12:34:45,510 - INFO - Scheduler started
2025-06-11 12:34:45,510 - INFO - Application started
2025-06-11 12:35:54,576 - ERROR - No error handlers are registered, logging exception.
Traceback (most recent call last):
  File "C:\Users\HP\AppData\Local\Programs\Python\Python313\Lib\site-packages\telegram\ext\_application.py", line 1298, in process_update
    await coroutine
  File "C:\Users\HP\AppData\Local\Programs\Python\Python313\Lib\site-packages\telegram\ext\_handlers\conversationhandler.py", line 842, in handle_update
    new_state: object = await handler.handle_update(
                        ^^^^^^^^^^^^^^^^^^^^^^^^^^^^
        update, application, handler_check_result, context
        ^^^^^^^^^^^^^^^^^^^^^^^^^^^^^^^^^^^^^^^^^^^^^^^^^^
    )
    ^
  File "C:\Users\HP\AppData\Local\Programs\Python\Python313\Lib\site-packages\telegram\ext\_handlers\basehandler.py", line 158, in handle_update
    return await self.callback(update, context)
           ^^^^^^^^^^^^^^^^^^^^^^^^^^^^^^^^^^^^
  File "D:\KonradDrive\Crypto_Way\Trade_bots\pairhelper\handlers\pairs.py", line 31, in start_pair_removal
    markup = build_pair_selection_keyboard(pairs)
  File "D:\KonradDrive\Crypto_Way\Trade_bots\pairhelper\handlers\pairs.py", line 11, in build_pair_selection_keyboard
    for pair_id, token_a, token_b, _ in pairs:
        ^^^^^^^^^^^^^^^^^^^^^^^^^^^^
ValueError: too many values to unpack (expected 4)
D:\KonradDrive\Crypto_Way\Trade_bots\pairhelper\main.py:69: PTBUserWarning: If 'per_message=False', 'CallbackQueryHandler' will not be tracked for every message. Read this FAQ entry to learn more about the per_* settings: https://github.com/python-telegram-bot/python-telegram-bot/wiki/Frequently-Asked-Questions#what-do-the-per_-settings-in-conversationhandler-do.
  remove_pairs_scene = ConversationHandler(
2025-06-11 12:39:23,431 - INFO - ✅ Бот запущено
2025-06-11 12:39:25,262 - INFO - Scheduler started
2025-06-11 12:39:25,262 - INFO - Application started
D:\KonradDrive\Crypto_Way\Trade_bots\pairhelper\main.py:69: PTBUserWarning: If 'per_message=False', 'CallbackQueryHandler' will not be tracked for every message. Read this FAQ entry to learn more about the per_* settings: https://github.com/python-telegram-bot/python-telegram-bot/wiki/Frequently-Asked-Questions#what-do-the-per_-settings-in-conversationhandler-do.
  remove_pairs_scene = ConversationHandler(
2025-06-11 12:39:50,996 - INFO - ✅ Бот запущено
2025-06-11 12:39:51,314 - INFO - Scheduler started
2025-06-11 12:39:51,314 - INFO - Application started
2025-06-11 12:40:54,738 - ERROR - No error handlers are registered, logging exception.
Traceback (most recent call last):
  File "C:\Users\HP\AppData\Local\Programs\Python\Python313\Lib\site-packages\telegram\ext\_application.py", line 1298, in process_update
    await coroutine
  File "C:\Users\HP\AppData\Local\Programs\Python\Python313\Lib\site-packages\telegram\ext\_handlers\conversationhandler.py", line 842, in handle_update
    new_state: object = await handler.handle_update(
                        ^^^^^^^^^^^^^^^^^^^^^^^^^^^^
        update, application, handler_check_result, context
        ^^^^^^^^^^^^^^^^^^^^^^^^^^^^^^^^^^^^^^^^^^^^^^^^^^
    )
    ^
  File "C:\Users\HP\AppData\Local\Programs\Python\Python313\Lib\site-packages\telegram\ext\_handlers\basehandler.py", line 158, in handle_update
    return await self.callback(update, context)
           ^^^^^^^^^^^^^^^^^^^^^^^^^^^^^^^^^^^^
  File "D:\KonradDrive\Crypto_Way\Trade_bots\pairhelper\handlers\pairs.py", line 41, in handle_pair_selection
    pair_id = int(data.split("_")[1])
ValueError: invalid literal for int() with base 10: 'id'
2025-06-11 12:40:55,427 - ERROR - No error handlers are registered, logging exception.
Traceback (most recent call last):
  File "C:\Users\HP\AppData\Local\Programs\Python\Python313\Lib\site-packages\telegram\ext\_application.py", line 1298, in process_update
    await coroutine
  File "C:\Users\HP\AppData\Local\Programs\Python\Python313\Lib\site-packages\telegram\ext\_handlers\conversationhandler.py", line 842, in handle_update
    new_state: object = await handler.handle_update(
                        ^^^^^^^^^^^^^^^^^^^^^^^^^^^^
        update, application, handler_check_result, context
        ^^^^^^^^^^^^^^^^^^^^^^^^^^^^^^^^^^^^^^^^^^^^^^^^^^
    )
    ^
  File "C:\Users\HP\AppData\Local\Programs\Python\Python313\Lib\site-packages\telegram\ext\_handlers\basehandler.py", line 158, in handle_update
    return await self.callback(update, context)
           ^^^^^^^^^^^^^^^^^^^^^^^^^^^^^^^^^^^^
  File "D:\KonradDrive\Crypto_Way\Trade_bots\pairhelper\handlers\pairs.py", line 41, in handle_pair_selection
    pair_id = int(data.split("_")[1])
ValueError: invalid literal for int() with base 10: 'id'
2025-06-11 12:40:56,337 - ERROR - No error handlers are registered, logging exception.
Traceback (most recent call last):
  File "C:\Users\HP\AppData\Local\Programs\Python\Python313\Lib\site-packages\telegram\ext\_application.py", line 1298, in process_update
    await coroutine
  File "C:\Users\HP\AppData\Local\Programs\Python\Python313\Lib\site-packages\telegram\ext\_handlers\conversationhandler.py", line 842, in handle_update
    new_state: object = await handler.handle_update(
                        ^^^^^^^^^^^^^^^^^^^^^^^^^^^^
        update, application, handler_check_result, context
        ^^^^^^^^^^^^^^^^^^^^^^^^^^^^^^^^^^^^^^^^^^^^^^^^^^
    )
    ^
  File "C:\Users\HP\AppData\Local\Programs\Python\Python313\Lib\site-packages\telegram\ext\_handlers\basehandler.py", line 158, in handle_update
    return await self.callback(update, context)
           ^^^^^^^^^^^^^^^^^^^^^^^^^^^^^^^^^^^^
  File "D:\KonradDrive\Crypto_Way\Trade_bots\pairhelper\handlers\pairs.py", line 41, in handle_pair_selection
    pair_id = int(data.split("_")[1])
ValueError: invalid literal for int() with base 10: 'id'
2025-06-11 12:40:57,128 - ERROR - No error handlers are registered, logging exception.
Traceback (most recent call last):
  File "C:\Users\HP\AppData\Local\Programs\Python\Python313\Lib\site-packages\telegram\ext\_application.py", line 1298, in process_update
    await coroutine
  File "C:\Users\HP\AppData\Local\Programs\Python\Python313\Lib\site-packages\telegram\ext\_handlers\conversationhandler.py", line 842, in handle_update
    new_state: object = await handler.handle_update(
                        ^^^^^^^^^^^^^^^^^^^^^^^^^^^^
        update, application, handler_check_result, context
        ^^^^^^^^^^^^^^^^^^^^^^^^^^^^^^^^^^^^^^^^^^^^^^^^^^
    )
    ^
  File "C:\Users\HP\AppData\Local\Programs\Python\Python313\Lib\site-packages\telegram\ext\_handlers\basehandler.py", line 158, in handle_update
    return await self.callback(update, context)
           ^^^^^^^^^^^^^^^^^^^^^^^^^^^^^^^^^^^^
  File "D:\KonradDrive\Crypto_Way\Trade_bots\pairhelper\handlers\pairs.py", line 41, in handle_pair_selection
    pair_id = int(data.split("_")[1])
ValueError: invalid literal for int() with base 10: 'id'
D:\KonradDrive\Crypto_Way\Trade_bots\pairhelper\main.py:69: PTBUserWarning: If 'per_message=False', 'CallbackQueryHandler' will not be tracked for every message. Read this FAQ entry to learn more about the per_* settings: https://github.com/python-telegram-bot/python-telegram-bot/wiki/Frequently-Asked-Questions#what-do-the-per_-settings-in-conversationhandler-do.
  remove_pairs_scene = ConversationHandler(
2025-06-11 12:44:47,292 - INFO - ✅ Бот запущено
D:\KonradDrive\Crypto_Way\Trade_bots\pairhelper\main.py:69: PTBUserWarning: If 'per_message=False', 'CallbackQueryHandler' will not be tracked for every message. Read this FAQ entry to learn more about the per_* settings: https://github.com/python-telegram-bot/python-telegram-bot/wiki/Frequently-Asked-Questions#what-do-the-per_-settings-in-conversationhandler-do.
  remove_pairs_scene = ConversationHandler(
2025-06-11 12:44:52,714 - INFO - ✅ Бот запущено
2025-06-11 12:44:53,074 - INFO - Scheduler started
2025-06-11 12:44:53,074 - INFO - Application started
2025-06-11 12:44:56,789 - ERROR - No error handlers are registered, logging exception.
Traceback (most recent call last):
  File "C:\Users\HP\AppData\Local\Programs\Python\Python313\Lib\site-packages\telegram\ext\_application.py", line 1298, in process_update
    await coroutine
  File "C:\Users\HP\AppData\Local\Programs\Python\Python313\Lib\site-packages\telegram\ext\_handlers\conversationhandler.py", line 842, in handle_update
    new_state: object = await handler.handle_update(
                        ^^^^^^^^^^^^^^^^^^^^^^^^^^^^
        update, application, handler_check_result, context
        ^^^^^^^^^^^^^^^^^^^^^^^^^^^^^^^^^^^^^^^^^^^^^^^^^^
    )
    ^
  File "C:\Users\HP\AppData\Local\Programs\Python\Python313\Lib\site-packages\telegram\ext\_handlers\basehandler.py", line 158, in handle_update
    return await self.callback(update, context)
           ^^^^^^^^^^^^^^^^^^^^^^^^^^^^^^^^^^^^
  File "D:\KonradDrive\Crypto_Way\Trade_bots\pairhelper\handlers\pairs.py", line 22, in start_pair_removal
    markup = build_pair_selection_keyboard(pairs)
  File "D:\KonradDrive\Crypto_Way\Trade_bots\pairhelper\handlers\pairs.py", line 10, in build_pair_selection_keyboard
    pair_id, token_a, token_b, _ = pair
    ^^^^^^^^^^^^^^^^^^^^^^^^^^^^
ValueError: too many values to unpack (expected 4)
D:\KonradDrive\Crypto_Way\Trade_bots\pairhelper\main.py:69: PTBUserWarning: If 'per_message=False', 'CallbackQueryHandler' will not be tracked for every message. Read this FAQ entry to learn more about the per_* settings: https://github.com/python-telegram-bot/python-telegram-bot/wiki/Frequently-Asked-Questions#what-do-the-per_-settings-in-conversationhandler-do.
  remove_pairs_scene = ConversationHandler(
2025-06-11 12:45:03,354 - INFO - ✅ Бот запущено
2025-06-11 12:45:03,672 - INFO - Scheduler started
2025-06-11 12:45:03,673 - INFO - Application started
2025-06-11 12:45:03,820 - ERROR - No error handlers are registered, logging exception.
Traceback (most recent call last):
  File "C:\Users\HP\AppData\Local\Programs\Python\Python313\Lib\site-packages\telegram\ext\_application.py", line 1298, in process_update
    await coroutine
  File "C:\Users\HP\AppData\Local\Programs\Python\Python313\Lib\site-packages\telegram\ext\_handlers\conversationhandler.py", line 842, in handle_update
    new_state: object = await handler.handle_update(
                        ^^^^^^^^^^^^^^^^^^^^^^^^^^^^
        update, application, handler_check_result, context
        ^^^^^^^^^^^^^^^^^^^^^^^^^^^^^^^^^^^^^^^^^^^^^^^^^^
    )
    ^
  File "C:\Users\HP\AppData\Local\Programs\Python\Python313\Lib\site-packages\telegram\ext\_handlers\basehandler.py", line 158, in handle_update
    return await self.callback(update, context)
           ^^^^^^^^^^^^^^^^^^^^^^^^^^^^^^^^^^^^
  File "D:\KonradDrive\Crypto_Way\Trade_bots\pairhelper\handlers\pairs.py", line 22, in start_pair_removal
    markup = build_pair_selection_keyboard(pairs)
  File "D:\KonradDrive\Crypto_Way\Trade_bots\pairhelper\handlers\pairs.py", line 10, in build_pair_selection_keyboard
    pair_id, token_a, token_b, _ = pair
    ^^^^^^^^^^^^^^^^^^^^^^^^^^^^
ValueError: too many values to unpack (expected 4)
2025-06-11 12:45:17,267 - ERROR - No error handlers are registered, logging exception.
Traceback (most recent call last):
  File "C:\Users\HP\AppData\Local\Programs\Python\Python313\Lib\site-packages\telegram\ext\_application.py", line 1298, in process_update
    await coroutine
  File "C:\Users\HP\AppData\Local\Programs\Python\Python313\Lib\site-packages\telegram\ext\_handlers\conversationhandler.py", line 842, in handle_update
    new_state: object = await handler.handle_update(
                        ^^^^^^^^^^^^^^^^^^^^^^^^^^^^
        update, application, handler_check_result, context
        ^^^^^^^^^^^^^^^^^^^^^^^^^^^^^^^^^^^^^^^^^^^^^^^^^^
    )
    ^
  File "C:\Users\HP\AppData\Local\Programs\Python\Python313\Lib\site-packages\telegram\ext\_handlers\basehandler.py", line 158, in handle_update
    return await self.callback(update, context)
           ^^^^^^^^^^^^^^^^^^^^^^^^^^^^^^^^^^^^
  File "D:\KonradDrive\Crypto_Way\Trade_bots\pairhelper\handlers\pairs.py", line 22, in start_pair_removal
    markup = build_pair_selection_keyboard(pairs)
  File "D:\KonradDrive\Crypto_Way\Trade_bots\pairhelper\handlers\pairs.py", line 10, in build_pair_selection_keyboard
    pair_id, token_a, token_b, _ = pair
    ^^^^^^^^^^^^^^^^^^^^^^^^^^^^
ValueError: too many values to unpack (expected 4)
D:\KonradDrive\Crypto_Way\Trade_bots\pairhelper\main.py:69: PTBUserWarning: If 'per_message=False', 'CallbackQueryHandler' will not be tracked for every message. Read this FAQ entry to learn more about the per_* settings: https://github.com/python-telegram-bot/python-telegram-bot/wiki/Frequently-Asked-Questions#what-do-the-per_-settings-in-conversationhandler-do.
  remove_pairs_scene = ConversationHandler(
2025-06-11 12:45:48,546 - INFO - ✅ Бот запущено
2025-06-11 12:45:48,877 - INFO - Scheduler started
2025-06-11 12:45:48,877 - INFO - Application started
D:\KonradDrive\Crypto_Way\Trade_bots\pairhelper\main.py:69: PTBUserWarning: If 'per_message=False', 'CallbackQueryHandler' will not be tracked for every message. Read this FAQ entry to learn more about the per_* settings: https://github.com/python-telegram-bot/python-telegram-bot/wiki/Frequently-Asked-Questions#what-do-the-per_-settings-in-conversationhandler-do.
  remove_pairs_scene = ConversationHandler(
2025-06-11 12:46:10,778 - INFO - ✅ Бот запущено
2025-06-11 12:46:11,094 - INFO - Scheduler started
2025-06-11 12:46:11,095 - INFO - Application started
D:\KonradDrive\Crypto_Way\Trade_bots\pairhelper\main.py:69: PTBUserWarning: If 'per_message=False', 'CallbackQueryHandler' will not be tracked for every message. Read this FAQ entry to learn more about the per_* settings: https://github.com/python-telegram-bot/python-telegram-bot/wiki/Frequently-Asked-Questions#what-do-the-per_-settings-in-conversationhandler-do.
  remove_pairs_scene = ConversationHandler(
2025-06-11 12:52:30,883 - INFO - ✅ Бот запущено
2025-06-11 12:52:31,203 - INFO - Scheduler started
2025-06-11 12:52:31,204 - INFO - Application started
D:\KonradDrive\Crypto_Way\Trade_bots\pairhelper\main.py:69: PTBUserWarning: If 'per_message=False', 'CallbackQueryHandler' will not be tracked for every message. Read this FAQ entry to learn more about the per_* settings: https://github.com/python-telegram-bot/python-telegram-bot/wiki/Frequently-Asked-Questions#what-do-the-per_-settings-in-conversationhandler-do.
  remove_pairs_scene = ConversationHandler(
2025-06-11 12:53:25,047 - INFO - ✅ Бот запущено
2025-06-11 12:53:25,380 - INFO - Scheduler started
2025-06-11 12:53:25,380 - INFO - Application started
D:\KonradDrive\Crypto_Way\Trade_bots\pairhelper\main.py:69: PTBUserWarning: If 'per_message=False', 'CallbackQueryHandler' will not be tracked for every message. Read this FAQ entry to learn more about the per_* settings: https://github.com/python-telegram-bot/python-telegram-bot/wiki/Frequently-Asked-Questions#what-do-the-per_-settings-in-conversationhandler-do.
  remove_pairs_scene = ConversationHandler(
2025-06-11 13:07:24,695 - INFO - ✅ Бот запущено
2025-06-11 13:07:25,219 - INFO - Scheduler started
2025-06-11 13:07:25,220 - INFO - Application started
Traceback (most recent call last):
  File "D:\KonradDrive\Crypto_Way\Trade_bots\pairhelper\main.py", line 70, in <module>
    entry_points=[MessageHandler(...)],
                  ~~~~~~~~~~~~~~^^^^^
TypeError: MessageHandler.__init__() missing 1 required positional argument: 'callback'
Traceback (most recent call last):
  File "D:\KonradDrive\Crypto_Way\Trade_bots\pairhelper\main.py", line 70, in <module>
    entry_points=[MessageHandler(...)],
                  ~~~~~~~~~~~~~~^^^^^
TypeError: MessageHandler.__init__() missing 1 required positional argument: 'callback'
D:\KonradDrive\Crypto_Way\Trade_bots\pairhelper\main.py:69: PTBUserWarning: If 'per_message=True', all entry points, state handlers, and fallbacks must be 'CallbackQueryHandler', since no other handlers have a message context. Read this FAQ entry to learn more about the per_* settings: https://github.com/python-telegram-bot/python-telegram-bot/wiki/Frequently-Asked-Questions#what-do-the-per_-settings-in-conversationhandler-do.
  remove_pairs_scene = ConversationHandler(
2025-06-11 13:09:34,344 - INFO - ✅ Бот запущено
2025-06-11 13:09:34,925 - INFO - Scheduler started
2025-06-11 13:09:34,926 - INFO - Application started
D:\KonradDrive\Crypto_Way\Trade_bots\pairhelper\main.py:69: PTBUserWarning: If 'per_message=True', all entry points, state handlers, and fallbacks must be 'CallbackQueryHandler', since no other handlers have a message context. Read this FAQ entry to learn more about the per_* settings: https://github.com/python-telegram-bot/python-telegram-bot/wiki/Frequently-Asked-Questions#what-do-the-per_-settings-in-conversationhandler-do.
  remove_pairs_scene = ConversationHandler(
2025-06-11 13:09:43,370 - INFO - ✅ Бот запущено
2025-06-11 13:09:43,678 - INFO - Scheduler started
2025-06-11 13:09:43,679 - INFO - Application started
D:\KonradDrive\Crypto_Way\Trade_bots\pairhelper\main.py:69: PTBUserWarning: If 'per_message=True', all entry points, state handlers, and fallbacks must be 'CallbackQueryHandler', since no other handlers have a message context. Read this FAQ entry to learn more about the per_* settings: https://github.com/python-telegram-bot/python-telegram-bot/wiki/Frequently-Asked-Questions#what-do-the-per_-settings-in-conversationhandler-do.
  remove_pairs_scene = ConversationHandler(
2025-06-11 13:13:22,406 - INFO - ✅ Бот запущено
2025-06-11 13:13:22,827 - INFO - Scheduler started
2025-06-11 13:13:22,828 - INFO - Application started
D:\KonradDrive\Crypto_Way\Trade_bots\pairhelper\main.py:69: PTBUserWarning: If 'per_message=True', all entry points, state handlers, and fallbacks must be 'CallbackQueryHandler', since no other handlers have a message context. Read this FAQ entry to learn more about the per_* settings: https://github.com/python-telegram-bot/python-telegram-bot/wiki/Frequently-Asked-Questions#what-do-the-per_-settings-in-conversationhandler-do.
  remove_pairs_scene = ConversationHandler(
2025-06-11 13:19:33,992 - INFO - ✅ Бот запущено
2025-06-11 13:19:34,314 - INFO - Scheduler started
2025-06-11 13:19:34,314 - INFO - Application started
D:\KonradDrive\Crypto_Way\Trade_bots\pairhelper\main.py:69: PTBUserWarning: If 'per_message=True', all entry points, state handlers, and fallbacks must be 'CallbackQueryHandler', since no other handlers have a message context. Read this FAQ entry to learn more about the per_* settings: https://github.com/python-telegram-bot/python-telegram-bot/wiki/Frequently-Asked-Questions#what-do-the-per_-settings-in-conversationhandler-do.
  remove_pairs_scene = ConversationHandler(
2025-06-11 13:20:09,994 - INFO - ✅ Бот запущено
2025-06-11 13:20:10,302 - INFO - Scheduler started
2025-06-11 13:20:10,302 - INFO - Application started
D:\KonradDrive\Crypto_Way\Trade_bots\pairhelper\main.py:70: PTBUserWarning: If 'per_message=True', all entry points, state handlers, and fallbacks must be 'CallbackQueryHandler', since no other handlers have a message context. Read this FAQ entry to learn more about the per_* settings: https://github.com/python-telegram-bot/python-telegram-bot/wiki/Frequently-Asked-Questions#what-do-the-per_-settings-in-conversationhandler-do.
  remove_pairs_scene = ConversationHandler(
2025-06-11 13:38:26,214 - INFO - ✅ Бот запущено
2025-06-11 13:38:26,554 - INFO - Scheduler started
2025-06-11 13:38:26,554 - INFO - Application started
D:\KonradDrive\Crypto_Way\Trade_bots\pairhelper\main.py:70: PTBUserWarning: If 'per_message=True', all entry points, state handlers, and fallbacks must be 'CallbackQueryHandler', since no other handlers have a message context. Read this FAQ entry to learn more about the per_* settings: https://github.com/python-telegram-bot/python-telegram-bot/wiki/Frequently-Asked-Questions#what-do-the-per_-settings-in-conversationhandler-do.
  remove_pairs_scene = ConversationHandler(
2025-06-11 13:39:04,666 - INFO - ✅ Бот запущено
2025-06-11 13:39:04,993 - INFO - Scheduler started
2025-06-11 13:39:04,993 - INFO - Application started
D:\KonradDrive\Crypto_Way\Trade_bots\pairhelper\main.py:69: PTBUserWarning: If 'per_message=False', 'CallbackQueryHandler' will not be tracked for every message. Read this FAQ entry to learn more about the per_* settings: https://github.com/python-telegram-bot/python-telegram-bot/wiki/Frequently-Asked-Questions#what-do-the-per_-settings-in-conversationhandler-do.
  remove_pairs_scene = ConversationHandler(
2025-06-11 13:47:14,252 - INFO - ✅ Бот запущено
D:\KonradDrive\Crypto_Way\Trade_bots\pairhelper\main.py:69: PTBUserWarning: If 'per_message=False', 'CallbackQueryHandler' will not be tracked for every message. Read this FAQ entry to learn more about the per_* settings: https://github.com/python-telegram-bot/python-telegram-bot/wiki/Frequently-Asked-Questions#what-do-the-per_-settings-in-conversationhandler-do.
  remove_pairs_scene = ConversationHandler(
2025-06-11 13:47:22,026 - INFO - ✅ Бот запущено
2025-06-11 13:47:22,385 - INFO - Scheduler started
2025-06-11 13:47:22,386 - INFO - Application started
D:\KonradDrive\Crypto_Way\Trade_bots\pairhelper\main.py:69: PTBUserWarning: If 'per_message=False', 'CallbackQueryHandler' will not be tracked for every message. Read this FAQ entry to learn more about the per_* settings: https://github.com/python-telegram-bot/python-telegram-bot/wiki/Frequently-Asked-Questions#what-do-the-per_-settings-in-conversationhandler-do.
  remove_pairs_scene = ConversationHandler(
2025-06-11 13:47:30,551 - INFO - ✅ Бот запущено
2025-06-11 13:47:30,871 - INFO - Scheduler started
2025-06-11 13:47:30,871 - INFO - Application started
D:\KonradDrive\Crypto_Way\Trade_bots\pairhelper\main.py:69: PTBUserWarning: If 'per_message=False', 'CallbackQueryHandler' will not be tracked for every message. Read this FAQ entry to learn more about the per_* settings: https://github.com/python-telegram-bot/python-telegram-bot/wiki/Frequently-Asked-Questions#what-do-the-per_-settings-in-conversationhandler-do.
  remove_pairs_scene = ConversationHandler(
2025-06-11 13:48:14,374 - INFO - ✅ Бот запущено
2025-06-11 13:48:14,724 - INFO - Scheduler started
2025-06-11 13:48:14,725 - INFO - Application started
D:\KonradDrive\Crypto_Way\Trade_bots\pairhelper\main.py:69: PTBUserWarning: If 'per_message=False', 'CallbackQueryHandler' will not be tracked for every message. Read this FAQ entry to learn more about the per_* settings: https://github.com/python-telegram-bot/python-telegram-bot/wiki/Frequently-Asked-Questions#what-do-the-per_-settings-in-conversationhandler-do.
  remove_pairs_scene = ConversationHandler(
2025-06-11 14:04:04,010 - INFO - ✅ Бот запущено
2025-06-11 14:04:04,445 - INFO - Scheduler started
2025-06-11 14:04:04,445 - INFO - Application started
D:\KonradDrive\Crypto_Way\Trade_bots\pairhelper\main.py:69: PTBUserWarning: If 'per_message=False', 'CallbackQueryHandler' will not be tracked for every message. Read this FAQ entry to learn more about the per_* settings: https://github.com/python-telegram-bot/python-telegram-bot/wiki/Frequently-Asked-Questions#what-do-the-per_-settings-in-conversationhandler-do.
  remove_pairs_scene = ConversationHandler(
2025-06-11 14:04:16,889 - INFO - ✅ Бот запущено
2025-06-11 14:04:17,244 - INFO - Scheduler started
2025-06-11 14:04:17,245 - INFO - Application started
D:\KonradDrive\Crypto_Way\Trade_bots\pairhelper\main.py:69: PTBUserWarning: If 'per_message=False', 'CallbackQueryHandler' will not be tracked for every message. Read this FAQ entry to learn more about the per_* settings: https://github.com/python-telegram-bot/python-telegram-bot/wiki/Frequently-Asked-Questions#what-do-the-per_-settings-in-conversationhandler-do.
  remove_pairs_scene = ConversationHandler(
2025-06-11 14:08:25,982 - INFO - ✅ Бот запущено
2025-06-11 14:08:26,466 - INFO - Scheduler started
2025-06-11 14:08:26,467 - INFO - Application started
D:\KonradDrive\Crypto_Way\Trade_bots\pairhelper\main.py:69: PTBUserWarning: If 'per_message=False', 'CallbackQueryHandler' will not be tracked for every message. Read this FAQ entry to learn more about the per_* settings: https://github.com/python-telegram-bot/python-telegram-bot/wiki/Frequently-Asked-Questions#what-do-the-per_-settings-in-conversationhandler-do.
  remove_pairs_scene = ConversationHandler(
2025-06-11 14:08:34,191 - INFO - ✅ Бот запущено
2025-06-11 14:08:34,531 - INFO - Scheduler started
2025-06-11 14:08:34,532 - INFO - Application started
D:\KonradDrive\Crypto_Way\Trade_bots\pairhelper\main.py:69: PTBUserWarning: If 'per_message=False', 'CallbackQueryHandler' will not be tracked for every message. Read this FAQ entry to learn more about the per_* settings: https://github.com/python-telegram-bot/python-telegram-bot/wiki/Frequently-Asked-Questions#what-do-the-per_-settings-in-conversationhandler-do.
  remove_pairs_scene = ConversationHandler(
2025-06-11 14:13:43,947 - INFO - ✅ Бот запущено
2025-06-11 14:13:44,439 - INFO - Scheduler started
2025-06-11 14:13:44,440 - INFO - Application started
D:\KonradDrive\Crypto_Way\Trade_bots\pairhelper\main.py:69: PTBUserWarning: If 'per_message=False', 'CallbackQueryHandler' will not be tracked for every message. Read this FAQ entry to learn more about the per_* settings: https://github.com/python-telegram-bot/python-telegram-bot/wiki/Frequently-Asked-Questions#what-do-the-per_-settings-in-conversationhandler-do.
  remove_pairs_scene = ConversationHandler(
2025-06-11 20:55:21,109 - INFO - ✅ Бот запущено
2025-06-11 20:55:21,541 - INFO - Scheduler started
2025-06-11 20:55:21,541 - INFO - Application started
D:\KonradDrive\Crypto_Way\Trade_bots\pairhelper\main.py:69: PTBUserWarning: If 'per_message=False', 'CallbackQueryHandler' will not be tracked for every message. Read this FAQ entry to learn more about the per_* settings: https://github.com/python-telegram-bot/python-telegram-bot/wiki/Frequently-Asked-Questions#what-do-the-per_-settings-in-conversationhandler-do.
  remove_pairs_scene = ConversationHandler(
2025-06-11 20:55:51,676 - INFO - ✅ Бот запущено
2025-06-11 20:55:52,112 - INFO - Scheduler started
2025-06-11 20:55:52,113 - INFO - Application started
D:\KonradDrive\Crypto_Way\Trade_bots\pairhelper\main.py:69: PTBUserWarning: If 'per_message=False', 'CallbackQueryHandler' will not be tracked for every message. Read this FAQ entry to learn more about the per_* settings: https://github.com/python-telegram-bot/python-telegram-bot/wiki/Frequently-Asked-Questions#what-do-the-per_-settings-in-conversationhandler-do.
  remove_pairs_scene = ConversationHandler(
2025-06-11 21:02:23,820 - INFO - ✅ Бот запущено
2025-06-11 21:02:24,326 - INFO - Scheduler started
2025-06-11 21:02:24,326 - INFO - Application started
D:\KonradDrive\Crypto_Way\Trade_bots\pairhelper\main.py:69: PTBUserWarning: If 'per_message=False', 'CallbackQueryHandler' will not be tracked for every message. Read this FAQ entry to learn more about the per_* settings: https://github.com/python-telegram-bot/python-telegram-bot/wiki/Frequently-Asked-Questions#what-do-the-per_-settings-in-conversationhandler-do.
  remove_pairs_scene = ConversationHandler(
2025-06-11 21:03:49,722 - INFO - ✅ Бот запущено
2025-06-11 21:03:50,049 - INFO - Scheduler started
2025-06-11 21:03:50,050 - INFO - Application started
D:\KonradDrive\Crypto_Way\Trade_bots\pairhelper\main.py:69: PTBUserWarning: If 'per_message=False', 'CallbackQueryHandler' will not be tracked for every message. Read this FAQ entry to learn more about the per_* settings: https://github.com/python-telegram-bot/python-telegram-bot/wiki/Frequently-Asked-Questions#what-do-the-per_-settings-in-conversationhandler-do.
  remove_pairs_scene = ConversationHandler(
2025-06-11 21:20:30,675 - INFO - \u2705 \u0411\u043e\u0442 \u0437\u0430\u043f\u0443\u0449\u0435\u043d\u043e
2025-06-11 21:20:31,156 - INFO - Scheduler started
2025-06-11 21:20:31,156 - INFO - Application started
D:\KonradDrive\Crypto_Way\Trade_bots\pairhelper\main.py:69: PTBUserWarning: If 'per_message=False', 'CallbackQueryHandler' will not be tracked for every message. Read this FAQ entry to learn more about the per_* settings: https://github.com/python-telegram-bot/python-telegram-bot/wiki/Frequently-Asked-Questions#what-do-the-per_-settings-in-conversationhandler-do.
  remove_pairs_scene = ConversationHandler(
2025-06-11 21:20:39,562 - INFO - \u2705 \u0411\u043e\u0442 \u0437\u0430\u043f\u0443\u0449\u0435\u043d\u043e
2025-06-11 21:20:39,867 - INFO - Scheduler started
2025-06-11 21:20:39,867 - INFO - Application started
D:\KonradDrive\Crypto_Way\Trade_bots\pairhelper\main.py:69: PTBUserWarning: If 'per_message=False', 'CallbackQueryHandler' will not be tracked for every message. Read this FAQ entry to learn more about the per_* settings: https://github.com/python-telegram-bot/python-telegram-bot/wiki/Frequently-Asked-Questions#what-do-the-per_-settings-in-conversationhandler-do.
  remove_pairs_scene = ConversationHandler(
2025-06-11 21:23:42,168 - INFO - \u2705 \u0411\u043e\u0442 \u0437\u0430\u043f\u0443\u0449\u0435\u043d\u043e
2025-06-11 21:23:42,623 - INFO - Scheduler started
2025-06-11 21:23:42,623 - INFO - Application started
2025-06-11 21:23:46,725 - INFO - \u25b6\ufe0f \u0412\u0438\u043a\u043b\u0438\u043a\u0430\u043d\u043e start_pair_removal
2025-06-11 21:23:46,726 - INFO - \U0001f50d \u041e\u0442\u0440\u0438\u043c\u0430\u043d\u043e 5 \u043f\u0430\u0440(\u0438) \u0437 \u0411\u0414
2025-06-11 21:23:46,729 - INFO - \U0001f50d \u041e\u0442\u0440\u0438\u043c\u0430\u043d\u043e 5 \u043f\u0430\u0440: [{'id': 5, 'token_a': 'BNB', 'token_b': 'SOL', 'cross_rate': 4.04708857710604, 'created_at': '2025-06-11T09:29:27.554079'}, {'id': 8, 'token_a': 'ARB', 'token_b': 'OP', 'cross_rate': 0.5651558073654391, 'created_at': '2025-06-11T10:20:04.217081'}, {'id': 9, 'token_a': 'ARB', 'token_b': 'BTC', 'cross_rate': 3.7651598676957e-06, 'created_at': '2025-06-11T18:03:35.907837'}, {'id': 10, 'token_a': 'BTC', 'token_b': 'ETH', 'cross_rate': 38.65463137324569, 'created_at': '2025-06-11T18:04:40.975314'}, {'id': 11, 'token_a': 'SOL', 'token_b': 'OP', 'cross_rate': 227.13091922005574, 'created_at': '2025-06-11T18:19:34.015979'}]
2025-06-11 21:23:49,820 - INFO - \U0001f5b1\ufe0f \u041e\u0431\u0440\u043e\u0431\u043a\u0430 callback: pairid_5
2025-06-11 21:23:49,820 - INFO - \u2705 \u041e\u0431\u0440\u0430\u043d\u043e/\u0437\u043d\u044f\u0442\u043e \u043f\u0430\u0440\u0443 \u0437 ID: 5
2025-06-11 21:23:49,821 - INFO - \U0001f50d \u041e\u0442\u0440\u0438\u043c\u0430\u043d\u043e 5 \u043f\u0430\u0440(\u0438) \u0437 \u0411\u0414
2025-06-11 21:23:49,822 - INFO - \U0001f501 \u041f\u0435\u0440\u0435\u0431\u0443\u0434\u043e\u0432\u0430 \u043a\u043b\u0430\u0432\u0456\u0430\u0442\u0443\u0440\u0438. \u041f\u043e\u0442\u043e\u0447\u043d\u0456 \u0432\u0438\u0431\u0440\u0430\u043d\u0456: {5}
2025-06-11 21:23:51,910 - INFO - \U0001f5b1\ufe0f \u041e\u0431\u0440\u043e\u0431\u043a\u0430 callback: pairid_5
2025-06-11 21:23:51,910 - INFO - \u2705 \u041e\u0431\u0440\u0430\u043d\u043e/\u0437\u043d\u044f\u0442\u043e \u043f\u0430\u0440\u0443 \u0437 ID: 5
2025-06-11 21:23:51,911 - INFO - \U0001f50d \u041e\u0442\u0440\u0438\u043c\u0430\u043d\u043e 5 \u043f\u0430\u0440(\u0438) \u0437 \u0411\u0414
2025-06-11 21:23:51,911 - INFO - \U0001f501 \u041f\u0435\u0440\u0435\u0431\u0443\u0434\u043e\u0432\u0430 \u043a\u043b\u0430\u0432\u0456\u0430\u0442\u0443\u0440\u0438. \u041f\u043e\u0442\u043e\u0447\u043d\u0456 \u0432\u0438\u0431\u0440\u0430\u043d\u0456: set()
2025-06-11 21:23:53,693 - INFO - \U0001f5b1\ufe0f \u041e\u0431\u0440\u043e\u0431\u043a\u0430 callback: delete_selected
2025-06-11 21:23:53,694 - INFO - \U0001f5d1\ufe0f \u0412\u0438\u0434\u0430\u043b\u044f\u0454\u043c\u043e \u043f\u0430\u0440\u0438: set()
D:\KonradDrive\Crypto_Way\Trade_bots\pairhelper\main.py:69: PTBUserWarning: If 'per_message=False', 'CallbackQueryHandler' will not be tracked for every message. Read this FAQ entry to learn more about the per_* settings: https://github.com/python-telegram-bot/python-telegram-bot/wiki/Frequently-Asked-Questions#what-do-the-per_-settings-in-conversationhandler-do.
  remove_pairs_scene = ConversationHandler(
2025-06-11 21:24:26,647 - INFO - \u2705 \u0411\u043e\u0442 \u0437\u0430\u043f\u0443\u0449\u0435\u043d\u043e
2025-06-11 21:24:26,992 - INFO - Scheduler started
2025-06-11 21:24:26,992 - INFO - Application started
2025-06-11 23:42:30,256 - ERROR - No error handlers are registered, logging exception.
Traceback (most recent call last):
  File "C:\Users\HP\AppData\Local\Programs\Python\Python313\Lib\site-packages\httpx\_transports\default.py", line 101, in map_httpcore_exceptions
    yield
  File "C:\Users\HP\AppData\Local\Programs\Python\Python313\Lib\site-packages\httpx\_transports\default.py", line 394, in handle_async_request
    resp = await self._pool.handle_async_request(req)
           ^^^^^^^^^^^^^^^^^^^^^^^^^^^^^^^^^^^^^^^^^^
  File "C:\Users\HP\AppData\Local\Programs\Python\Python313\Lib\site-packages\httpcore\_async\connection_pool.py", line 256, in handle_async_request
    raise exc from None
  File "C:\Users\HP\AppData\Local\Programs\Python\Python313\Lib\site-packages\httpcore\_async\connection_pool.py", line 236, in handle_async_request
    response = await connection.handle_async_request(
               ^^^^^^^^^^^^^^^^^^^^^^^^^^^^^^^^^^^^^^
        pool_request.request
        ^^^^^^^^^^^^^^^^^^^^
    )
    ^
  File "C:\Users\HP\AppData\Local\Programs\Python\Python313\Lib\site-packages\httpcore\_async\connection.py", line 101, in handle_async_request
    raise exc
  File "C:\Users\HP\AppData\Local\Programs\Python\Python313\Lib\site-packages\httpcore\_async\connection.py", line 78, in handle_async_request
    stream = await self._connect(request)
             ^^^^^^^^^^^^^^^^^^^^^^^^^^^^
  File "C:\Users\HP\AppData\Local\Programs\Python\Python313\Lib\site-packages\httpcore\_async\connection.py", line 124, in _connect
    stream = await self._network_backend.connect_tcp(**kwargs)
             ^^^^^^^^^^^^^^^^^^^^^^^^^^^^^^^^^^^^^^^^^^^^^^^^^
  File "C:\Users\HP\AppData\Local\Programs\Python\Python313\Lib\site-packages\httpcore\_backends\auto.py", line 31, in connect_tcp
    return await self._backend.connect_tcp(
           ^^^^^^^^^^^^^^^^^^^^^^^^^^^^^^^^
    ...<5 lines>...
    )
    ^
  File "C:\Users\HP\AppData\Local\Programs\Python\Python313\Lib\site-packages\httpcore\_backends\anyio.py", line 113, in connect_tcp
    with map_exceptions(exc_map):
         ~~~~~~~~~~~~~~^^^^^^^^^
  File "C:\Users\HP\AppData\Local\Programs\Python\Python313\Lib\contextlib.py", line 162, in __exit__
    self.gen.throw(value)
    ~~~~~~~~~~~~~~^^^^^^^
  File "C:\Users\HP\AppData\Local\Programs\Python\Python313\Lib\site-packages\httpcore\_exceptions.py", line 14, in map_exceptions
    raise to_exc(exc) from exc
httpcore.ConnectError: [Errno 11001] getaddrinfo failed

The above exception was the direct cause of the following exception:

Traceback (most recent call last):
  File "C:\Users\HP\AppData\Local\Programs\Python\Python313\Lib\site-packages\telegram\request\_httpxrequest.py", line 273, in do_request
    res = await self._client.request(
          ^^^^^^^^^^^^^^^^^^^^^^^^^^^
    ...<6 lines>...
    )
    ^
  File "C:\Users\HP\AppData\Local\Programs\Python\Python313\Lib\site-packages\httpx\_client.py", line 1540, in request
    return await self.send(request, auth=auth, follow_redirects=follow_redirects)
           ^^^^^^^^^^^^^^^^^^^^^^^^^^^^^^^^^^^^^^^^^^^^^^^^^^^^^^^^^^^^^^^^^^^^^^
  File "C:\Users\HP\AppData\Local\Programs\Python\Python313\Lib\site-packages\httpx\_client.py", line 1629, in send
    response = await self._send_handling_auth(
               ^^^^^^^^^^^^^^^^^^^^^^^^^^^^^^^
    ...<4 lines>...
    )
    ^
  File "C:\Users\HP\AppData\Local\Programs\Python\Python313\Lib\site-packages\httpx\_client.py", line 1657, in _send_handling_auth
    response = await self._send_handling_redirects(
               ^^^^^^^^^^^^^^^^^^^^^^^^^^^^^^^^^^^^
    ...<3 lines>...
    )
    ^
  File "C:\Users\HP\AppData\Local\Programs\Python\Python313\Lib\site-packages\httpx\_client.py", line 1694, in _send_handling_redirects
    response = await self._send_single_request(request)
               ^^^^^^^^^^^^^^^^^^^^^^^^^^^^^^^^^^^^^^^^
  File "C:\Users\HP\AppData\Local\Programs\Python\Python313\Lib\site-packages\httpx\_client.py", line 1730, in _send_single_request
    response = await transport.handle_async_request(request)
               ^^^^^^^^^^^^^^^^^^^^^^^^^^^^^^^^^^^^^^^^^^^^^
  File "C:\Users\HP\AppData\Local\Programs\Python\Python313\Lib\site-packages\httpx\_transports\default.py", line 393, in handle_async_request
    with map_httpcore_exceptions():
         ~~~~~~~~~~~~~~~~~~~~~~~^^
  File "C:\Users\HP\AppData\Local\Programs\Python\Python313\Lib\contextlib.py", line 162, in __exit__
    self.gen.throw(value)
    ~~~~~~~~~~~~~~^^^^^^^
  File "C:\Users\HP\AppData\Local\Programs\Python\Python313\Lib\site-packages\httpx\_transports\default.py", line 118, in map_httpcore_exceptions
    raise mapped_exc(message) from exc
httpx.ConnectError: [Errno 11001] getaddrinfo failed

The above exception was the direct cause of the following exception:

Traceback (most recent call last):
  File "C:\Users\HP\AppData\Local\Programs\Python\Python313\Lib\site-packages\telegram\ext\_utils\networkloop.py", line 115, in network_retry_loop
    if not await do_action():
           ^^^^^^^^^^^^^^^^^
  File "C:\Users\HP\AppData\Local\Programs\Python\Python313\Lib\site-packages\telegram\ext\_utils\networkloop.py", line 108, in do_action
    return action_cb_task.result()
           ~~~~~~~~~~~~~~~~~~~~~^^
  File "C:\Users\HP\AppData\Local\Programs\Python\Python313\Lib\site-packages\telegram\ext\_updater.py", line 335, in polling_action_cb
    updates = await self.bot.get_updates(
              ^^^^^^^^^^^^^^^^^^^^^^^^^^^
    ...<3 lines>...
    )
    ^
  File "C:\Users\HP\AppData\Local\Programs\Python\Python313\Lib\site-packages\telegram\ext\_extbot.py", line 669, in get_updates
    updates = await super().get_updates(
              ^^^^^^^^^^^^^^^^^^^^^^^^^^
    ...<9 lines>...
    )
    ^
  File "C:\Users\HP\AppData\Local\Programs\Python\Python313\Lib\site-packages\telegram\_bot.py", line 4601, in get_updates
    await self._post(
    ^^^^^^^^^^^^^^^^^
    ...<7 lines>...
    ),
    ^
  File "C:\Users\HP\AppData\Local\Programs\Python\Python313\Lib\site-packages\telegram\_bot.py", line 697, in _post
    return await self._do_post(
           ^^^^^^^^^^^^^^^^^^^^
    ...<6 lines>...
    )
    ^
  File "C:\Users\HP\AppData\Local\Programs\Python\Python313\Lib\site-packages\telegram\ext\_extbot.py", line 369, in _do_post
    return await super()._do_post(
           ^^^^^^^^^^^^^^^^^^^^^^^
    ...<6 lines>...
    )
    ^
  File "C:\Users\HP\AppData\Local\Programs\Python\Python313\Lib\site-packages\telegram\_bot.py", line 726, in _do_post
    result = await request.post(
             ^^^^^^^^^^^^^^^^^^^
    ...<6 lines>...
    )
    ^
  File "C:\Users\HP\AppData\Local\Programs\Python\Python313\Lib\site-packages\telegram\request\_baserequest.py", line 197, in post
    result = await self._request_wrapper(
             ^^^^^^^^^^^^^^^^^^^^^^^^^^^^
    ...<7 lines>...
    )
    ^
  File "C:\Users\HP\AppData\Local\Programs\Python\Python313\Lib\site-packages\telegram\request\_baserequest.py", line 304, in _request_wrapper
    code, payload = await self.do_request(
                    ^^^^^^^^^^^^^^^^^^^^^^
    ...<7 lines>...
    )
    ^
  File "C:\Users\HP\AppData\Local\Programs\Python\Python313\Lib\site-packages\telegram\request\_httpxrequest.py", line 297, in do_request
    raise NetworkError(f"httpx.{err.__class__.__name__}: {err}") from err
telegram.error.NetworkError: httpx.ConnectError: [Errno 11001] getaddrinfo failed
2025-06-11 23:42:32,598 - ERROR - No error handlers are registered, logging exception.
Traceback (most recent call last):
  File "C:\Users\HP\AppData\Local\Programs\Python\Python313\Lib\site-packages\httpx\_transports\default.py", line 101, in map_httpcore_exceptions
    yield
  File "C:\Users\HP\AppData\Local\Programs\Python\Python313\Lib\site-packages\httpx\_transports\default.py", line 394, in handle_async_request
    resp = await self._pool.handle_async_request(req)
           ^^^^^^^^^^^^^^^^^^^^^^^^^^^^^^^^^^^^^^^^^^
  File "C:\Users\HP\AppData\Local\Programs\Python\Python313\Lib\site-packages\httpcore\_async\connection_pool.py", line 256, in handle_async_request
    raise exc from None
  File "C:\Users\HP\AppData\Local\Programs\Python\Python313\Lib\site-packages\httpcore\_async\connection_pool.py", line 236, in handle_async_request
    response = await connection.handle_async_request(
               ^^^^^^^^^^^^^^^^^^^^^^^^^^^^^^^^^^^^^^
        pool_request.request
        ^^^^^^^^^^^^^^^^^^^^
    )
    ^
  File "C:\Users\HP\AppData\Local\Programs\Python\Python313\Lib\site-packages\httpcore\_async\connection.py", line 101, in handle_async_request
    raise exc
  File "C:\Users\HP\AppData\Local\Programs\Python\Python313\Lib\site-packages\httpcore\_async\connection.py", line 78, in handle_async_request
    stream = await self._connect(request)
             ^^^^^^^^^^^^^^^^^^^^^^^^^^^^
  File "C:\Users\HP\AppData\Local\Programs\Python\Python313\Lib\site-packages\httpcore\_async\connection.py", line 124, in _connect
    stream = await self._network_backend.connect_tcp(**kwargs)
             ^^^^^^^^^^^^^^^^^^^^^^^^^^^^^^^^^^^^^^^^^^^^^^^^^
  File "C:\Users\HP\AppData\Local\Programs\Python\Python313\Lib\site-packages\httpcore\_backends\auto.py", line 31, in connect_tcp
    return await self._backend.connect_tcp(
           ^^^^^^^^^^^^^^^^^^^^^^^^^^^^^^^^
    ...<5 lines>...
    )
    ^
  File "C:\Users\HP\AppData\Local\Programs\Python\Python313\Lib\site-packages\httpcore\_backends\anyio.py", line 113, in connect_tcp
    with map_exceptions(exc_map):
         ~~~~~~~~~~~~~~^^^^^^^^^
  File "C:\Users\HP\AppData\Local\Programs\Python\Python313\Lib\contextlib.py", line 162, in __exit__
    self.gen.throw(value)
    ~~~~~~~~~~~~~~^^^^^^^
  File "C:\Users\HP\AppData\Local\Programs\Python\Python313\Lib\site-packages\httpcore\_exceptions.py", line 14, in map_exceptions
    raise to_exc(exc) from exc
httpcore.ConnectError: [Errno 11001] getaddrinfo failed

The above exception was the direct cause of the following exception:

Traceback (most recent call last):
  File "C:\Users\HP\AppData\Local\Programs\Python\Python313\Lib\site-packages\telegram\request\_httpxrequest.py", line 273, in do_request
    res = await self._client.request(
          ^^^^^^^^^^^^^^^^^^^^^^^^^^^
    ...<6 lines>...
    )
    ^
  File "C:\Users\HP\AppData\Local\Programs\Python\Python313\Lib\site-packages\httpx\_client.py", line 1540, in request
    return await self.send(request, auth=auth, follow_redirects=follow_redirects)
           ^^^^^^^^^^^^^^^^^^^^^^^^^^^^^^^^^^^^^^^^^^^^^^^^^^^^^^^^^^^^^^^^^^^^^^
  File "C:\Users\HP\AppData\Local\Programs\Python\Python313\Lib\site-packages\httpx\_client.py", line 1629, in send
    response = await self._send_handling_auth(
               ^^^^^^^^^^^^^^^^^^^^^^^^^^^^^^^
    ...<4 lines>...
    )
    ^
  File "C:\Users\HP\AppData\Local\Programs\Python\Python313\Lib\site-packages\httpx\_client.py", line 1657, in _send_handling_auth
    response = await self._send_handling_redirects(
               ^^^^^^^^^^^^^^^^^^^^^^^^^^^^^^^^^^^^
    ...<3 lines>...
    )
    ^
  File "C:\Users\HP\AppData\Local\Programs\Python\Python313\Lib\site-packages\httpx\_client.py", line 1694, in _send_handling_redirects
    response = await self._send_single_request(request)
               ^^^^^^^^^^^^^^^^^^^^^^^^^^^^^^^^^^^^^^^^
  File "C:\Users\HP\AppData\Local\Programs\Python\Python313\Lib\site-packages\httpx\_client.py", line 1730, in _send_single_request
    response = await transport.handle_async_request(request)
               ^^^^^^^^^^^^^^^^^^^^^^^^^^^^^^^^^^^^^^^^^^^^^
  File "C:\Users\HP\AppData\Local\Programs\Python\Python313\Lib\site-packages\httpx\_transports\default.py", line 393, in handle_async_request
    with map_httpcore_exceptions():
         ~~~~~~~~~~~~~~~~~~~~~~~^^
  File "C:\Users\HP\AppData\Local\Programs\Python\Python313\Lib\contextlib.py", line 162, in __exit__
    self.gen.throw(value)
    ~~~~~~~~~~~~~~^^^^^^^
  File "C:\Users\HP\AppData\Local\Programs\Python\Python313\Lib\site-packages\httpx\_transports\default.py", line 118, in map_httpcore_exceptions
    raise mapped_exc(message) from exc
httpx.ConnectError: [Errno 11001] getaddrinfo failed

The above exception was the direct cause of the following exception:

Traceback (most recent call last):
  File "C:\Users\HP\AppData\Local\Programs\Python\Python313\Lib\site-packages\telegram\ext\_utils\networkloop.py", line 115, in network_retry_loop
    if not await do_action():
           ^^^^^^^^^^^^^^^^^
  File "C:\Users\HP\AppData\Local\Programs\Python\Python313\Lib\site-packages\telegram\ext\_utils\networkloop.py", line 108, in do_action
    return action_cb_task.result()
           ~~~~~~~~~~~~~~~~~~~~~^^
  File "C:\Users\HP\AppData\Local\Programs\Python\Python313\Lib\site-packages\telegram\ext\_updater.py", line 335, in polling_action_cb
    updates = await self.bot.get_updates(
              ^^^^^^^^^^^^^^^^^^^^^^^^^^^
    ...<3 lines>...
    )
    ^
  File "C:\Users\HP\AppData\Local\Programs\Python\Python313\Lib\site-packages\telegram\ext\_extbot.py", line 669, in get_updates
    updates = await super().get_updates(
              ^^^^^^^^^^^^^^^^^^^^^^^^^^
    ...<9 lines>...
    )
    ^
  File "C:\Users\HP\AppData\Local\Programs\Python\Python313\Lib\site-packages\telegram\_bot.py", line 4601, in get_updates
    await self._post(
    ^^^^^^^^^^^^^^^^^
    ...<7 lines>...
    ),
    ^
  File "C:\Users\HP\AppData\Local\Programs\Python\Python313\Lib\site-packages\telegram\_bot.py", line 697, in _post
    return await self._do_post(
           ^^^^^^^^^^^^^^^^^^^^
    ...<6 lines>...
    )
    ^
  File "C:\Users\HP\AppData\Local\Programs\Python\Python313\Lib\site-packages\telegram\ext\_extbot.py", line 369, in _do_post
    return await super()._do_post(
           ^^^^^^^^^^^^^^^^^^^^^^^
    ...<6 lines>...
    )
    ^
  File "C:\Users\HP\AppData\Local\Programs\Python\Python313\Lib\site-packages\telegram\_bot.py", line 726, in _do_post
    result = await request.post(
             ^^^^^^^^^^^^^^^^^^^
    ...<6 lines>...
    )
    ^
  File "C:\Users\HP\AppData\Local\Programs\Python\Python313\Lib\site-packages\telegram\request\_baserequest.py", line 197, in post
    result = await self._request_wrapper(
             ^^^^^^^^^^^^^^^^^^^^^^^^^^^^
    ...<7 lines>...
    )
    ^
  File "C:\Users\HP\AppData\Local\Programs\Python\Python313\Lib\site-packages\telegram\request\_baserequest.py", line 304, in _request_wrapper
    code, payload = await self.do_request(
                    ^^^^^^^^^^^^^^^^^^^^^^
    ...<7 lines>...
    )
    ^
  File "C:\Users\HP\AppData\Local\Programs\Python\Python313\Lib\site-packages\telegram\request\_httpxrequest.py", line 297, in do_request
    raise NetworkError(f"httpx.{err.__class__.__name__}: {err}") from err
telegram.error.NetworkError: httpx.ConnectError: [Errno 11001] getaddrinfo failed
2025-06-11 23:42:34,110 - ERROR - No error handlers are registered, logging exception.
Traceback (most recent call last):
  File "C:\Users\HP\AppData\Local\Programs\Python\Python313\Lib\site-packages\httpx\_transports\default.py", line 101, in map_httpcore_exceptions
    yield
  File "C:\Users\HP\AppData\Local\Programs\Python\Python313\Lib\site-packages\httpx\_transports\default.py", line 394, in handle_async_request
    resp = await self._pool.handle_async_request(req)
           ^^^^^^^^^^^^^^^^^^^^^^^^^^^^^^^^^^^^^^^^^^
  File "C:\Users\HP\AppData\Local\Programs\Python\Python313\Lib\site-packages\httpcore\_async\connection_pool.py", line 256, in handle_async_request
    raise exc from None
  File "C:\Users\HP\AppData\Local\Programs\Python\Python313\Lib\site-packages\httpcore\_async\connection_pool.py", line 236, in handle_async_request
    response = await connection.handle_async_request(
               ^^^^^^^^^^^^^^^^^^^^^^^^^^^^^^^^^^^^^^
        pool_request.request
        ^^^^^^^^^^^^^^^^^^^^
    )
    ^
  File "C:\Users\HP\AppData\Local\Programs\Python\Python313\Lib\site-packages\httpcore\_async\connection.py", line 101, in handle_async_request
    raise exc
  File "C:\Users\HP\AppData\Local\Programs\Python\Python313\Lib\site-packages\httpcore\_async\connection.py", line 78, in handle_async_request
    stream = await self._connect(request)
             ^^^^^^^^^^^^^^^^^^^^^^^^^^^^
  File "C:\Users\HP\AppData\Local\Programs\Python\Python313\Lib\site-packages\httpcore\_async\connection.py", line 124, in _connect
    stream = await self._network_backend.connect_tcp(**kwargs)
             ^^^^^^^^^^^^^^^^^^^^^^^^^^^^^^^^^^^^^^^^^^^^^^^^^
  File "C:\Users\HP\AppData\Local\Programs\Python\Python313\Lib\site-packages\httpcore\_backends\auto.py", line 31, in connect_tcp
    return await self._backend.connect_tcp(
           ^^^^^^^^^^^^^^^^^^^^^^^^^^^^^^^^
    ...<5 lines>...
    )
    ^
  File "C:\Users\HP\AppData\Local\Programs\Python\Python313\Lib\site-packages\httpcore\_backends\anyio.py", line 113, in connect_tcp
    with map_exceptions(exc_map):
         ~~~~~~~~~~~~~~^^^^^^^^^
  File "C:\Users\HP\AppData\Local\Programs\Python\Python313\Lib\contextlib.py", line 162, in __exit__
    self.gen.throw(value)
    ~~~~~~~~~~~~~~^^^^^^^
  File "C:\Users\HP\AppData\Local\Programs\Python\Python313\Lib\site-packages\httpcore\_exceptions.py", line 14, in map_exceptions
    raise to_exc(exc) from exc
httpcore.ConnectError: [Errno 11001] getaddrinfo failed

The above exception was the direct cause of the following exception:

Traceback (most recent call last):
  File "C:\Users\HP\AppData\Local\Programs\Python\Python313\Lib\site-packages\telegram\request\_httpxrequest.py", line 273, in do_request
    res = await self._client.request(
          ^^^^^^^^^^^^^^^^^^^^^^^^^^^
    ...<6 lines>...
    )
    ^
  File "C:\Users\HP\AppData\Local\Programs\Python\Python313\Lib\site-packages\httpx\_client.py", line 1540, in request
    return await self.send(request, auth=auth, follow_redirects=follow_redirects)
           ^^^^^^^^^^^^^^^^^^^^^^^^^^^^^^^^^^^^^^^^^^^^^^^^^^^^^^^^^^^^^^^^^^^^^^
  File "C:\Users\HP\AppData\Local\Programs\Python\Python313\Lib\site-packages\httpx\_client.py", line 1629, in send
    response = await self._send_handling_auth(
               ^^^^^^^^^^^^^^^^^^^^^^^^^^^^^^^
    ...<4 lines>...
    )
    ^
  File "C:\Users\HP\AppData\Local\Programs\Python\Python313\Lib\site-packages\httpx\_client.py", line 1657, in _send_handling_auth
    response = await self._send_handling_redirects(
               ^^^^^^^^^^^^^^^^^^^^^^^^^^^^^^^^^^^^
    ...<3 lines>...
    )
    ^
  File "C:\Users\HP\AppData\Local\Programs\Python\Python313\Lib\site-packages\httpx\_client.py", line 1694, in _send_handling_redirects
    response = await self._send_single_request(request)
               ^^^^^^^^^^^^^^^^^^^^^^^^^^^^^^^^^^^^^^^^
  File "C:\Users\HP\AppData\Local\Programs\Python\Python313\Lib\site-packages\httpx\_client.py", line 1730, in _send_single_request
    response = await transport.handle_async_request(request)
               ^^^^^^^^^^^^^^^^^^^^^^^^^^^^^^^^^^^^^^^^^^^^^
  File "C:\Users\HP\AppData\Local\Programs\Python\Python313\Lib\site-packages\httpx\_transports\default.py", line 393, in handle_async_request
    with map_httpcore_exceptions():
         ~~~~~~~~~~~~~~~~~~~~~~~^^
  File "C:\Users\HP\AppData\Local\Programs\Python\Python313\Lib\contextlib.py", line 162, in __exit__
    self.gen.throw(value)
    ~~~~~~~~~~~~~~^^^^^^^
  File "C:\Users\HP\AppData\Local\Programs\Python\Python313\Lib\site-packages\httpx\_transports\default.py", line 118, in map_httpcore_exceptions
    raise mapped_exc(message) from exc
httpx.ConnectError: [Errno 11001] getaddrinfo failed

The above exception was the direct cause of the following exception:

Traceback (most recent call last):
  File "C:\Users\HP\AppData\Local\Programs\Python\Python313\Lib\site-packages\telegram\ext\_utils\networkloop.py", line 115, in network_retry_loop
    if not await do_action():
           ^^^^^^^^^^^^^^^^^
  File "C:\Users\HP\AppData\Local\Programs\Python\Python313\Lib\site-packages\telegram\ext\_utils\networkloop.py", line 108, in do_action
    return action_cb_task.result()
           ~~~~~~~~~~~~~~~~~~~~~^^
  File "C:\Users\HP\AppData\Local\Programs\Python\Python313\Lib\site-packages\telegram\ext\_updater.py", line 335, in polling_action_cb
    updates = await self.bot.get_updates(
              ^^^^^^^^^^^^^^^^^^^^^^^^^^^
    ...<3 lines>...
    )
    ^
  File "C:\Users\HP\AppData\Local\Programs\Python\Python313\Lib\site-packages\telegram\ext\_extbot.py", line 669, in get_updates
    updates = await super().get_updates(
              ^^^^^^^^^^^^^^^^^^^^^^^^^^
    ...<9 lines>...
    )
    ^
  File "C:\Users\HP\AppData\Local\Programs\Python\Python313\Lib\site-packages\telegram\_bot.py", line 4601, in get_updates
    await self._post(
    ^^^^^^^^^^^^^^^^^
    ...<7 lines>...
    ),
    ^
  File "C:\Users\HP\AppData\Local\Programs\Python\Python313\Lib\site-packages\telegram\_bot.py", line 697, in _post
    return await self._do_post(
           ^^^^^^^^^^^^^^^^^^^^
    ...<6 lines>...
    )
    ^
  File "C:\Users\HP\AppData\Local\Programs\Python\Python313\Lib\site-packages\telegram\ext\_extbot.py", line 369, in _do_post
    return await super()._do_post(
           ^^^^^^^^^^^^^^^^^^^^^^^
    ...<6 lines>...
    )
    ^
  File "C:\Users\HP\AppData\Local\Programs\Python\Python313\Lib\site-packages\telegram\_bot.py", line 726, in _do_post
    result = await request.post(
             ^^^^^^^^^^^^^^^^^^^
    ...<6 lines>...
    )
    ^
  File "C:\Users\HP\AppData\Local\Programs\Python\Python313\Lib\site-packages\telegram\request\_baserequest.py", line 197, in post
    result = await self._request_wrapper(
             ^^^^^^^^^^^^^^^^^^^^^^^^^^^^
    ...<7 lines>...
    )
    ^
  File "C:\Users\HP\AppData\Local\Programs\Python\Python313\Lib\site-packages\telegram\request\_baserequest.py", line 304, in _request_wrapper
    code, payload = await self.do_request(
                    ^^^^^^^^^^^^^^^^^^^^^^
    ...<7 lines>...
    )
    ^
  File "C:\Users\HP\AppData\Local\Programs\Python\Python313\Lib\site-packages\telegram\request\_httpxrequest.py", line 297, in do_request
    raise NetworkError(f"httpx.{err.__class__.__name__}: {err}") from err
telegram.error.NetworkError: httpx.ConnectError: [Errno 11001] getaddrinfo failed
2025-06-11 23:42:36,365 - ERROR - No error handlers are registered, logging exception.
Traceback (most recent call last):
  File "C:\Users\HP\AppData\Local\Programs\Python\Python313\Lib\site-packages\httpx\_transports\default.py", line 101, in map_httpcore_exceptions
    yield
  File "C:\Users\HP\AppData\Local\Programs\Python\Python313\Lib\site-packages\httpx\_transports\default.py", line 394, in handle_async_request
    resp = await self._pool.handle_async_request(req)
           ^^^^^^^^^^^^^^^^^^^^^^^^^^^^^^^^^^^^^^^^^^
  File "C:\Users\HP\AppData\Local\Programs\Python\Python313\Lib\site-packages\httpcore\_async\connection_pool.py", line 256, in handle_async_request
    raise exc from None
  File "C:\Users\HP\AppData\Local\Programs\Python\Python313\Lib\site-packages\httpcore\_async\connection_pool.py", line 236, in handle_async_request
    response = await connection.handle_async_request(
               ^^^^^^^^^^^^^^^^^^^^^^^^^^^^^^^^^^^^^^
        pool_request.request
        ^^^^^^^^^^^^^^^^^^^^
    )
    ^
  File "C:\Users\HP\AppData\Local\Programs\Python\Python313\Lib\site-packages\httpcore\_async\connection.py", line 101, in handle_async_request
    raise exc
  File "C:\Users\HP\AppData\Local\Programs\Python\Python313\Lib\site-packages\httpcore\_async\connection.py", line 78, in handle_async_request
    stream = await self._connect(request)
             ^^^^^^^^^^^^^^^^^^^^^^^^^^^^
  File "C:\Users\HP\AppData\Local\Programs\Python\Python313\Lib\site-packages\httpcore\_async\connection.py", line 124, in _connect
    stream = await self._network_backend.connect_tcp(**kwargs)
             ^^^^^^^^^^^^^^^^^^^^^^^^^^^^^^^^^^^^^^^^^^^^^^^^^
  File "C:\Users\HP\AppData\Local\Programs\Python\Python313\Lib\site-packages\httpcore\_backends\auto.py", line 31, in connect_tcp
    return await self._backend.connect_tcp(
           ^^^^^^^^^^^^^^^^^^^^^^^^^^^^^^^^
    ...<5 lines>...
    )
    ^
  File "C:\Users\HP\AppData\Local\Programs\Python\Python313\Lib\site-packages\httpcore\_backends\anyio.py", line 113, in connect_tcp
    with map_exceptions(exc_map):
         ~~~~~~~~~~~~~~^^^^^^^^^
  File "C:\Users\HP\AppData\Local\Programs\Python\Python313\Lib\contextlib.py", line 162, in __exit__
    self.gen.throw(value)
    ~~~~~~~~~~~~~~^^^^^^^
  File "C:\Users\HP\AppData\Local\Programs\Python\Python313\Lib\site-packages\httpcore\_exceptions.py", line 14, in map_exceptions
    raise to_exc(exc) from exc
httpcore.ConnectError: [Errno 11001] getaddrinfo failed

The above exception was the direct cause of the following exception:

Traceback (most recent call last):
  File "C:\Users\HP\AppData\Local\Programs\Python\Python313\Lib\site-packages\telegram\request\_httpxrequest.py", line 273, in do_request
    res = await self._client.request(
          ^^^^^^^^^^^^^^^^^^^^^^^^^^^
    ...<6 lines>...
    )
    ^
  File "C:\Users\HP\AppData\Local\Programs\Python\Python313\Lib\site-packages\httpx\_client.py", line 1540, in request
    return await self.send(request, auth=auth, follow_redirects=follow_redirects)
           ^^^^^^^^^^^^^^^^^^^^^^^^^^^^^^^^^^^^^^^^^^^^^^^^^^^^^^^^^^^^^^^^^^^^^^
  File "C:\Users\HP\AppData\Local\Programs\Python\Python313\Lib\site-packages\httpx\_client.py", line 1629, in send
    response = await self._send_handling_auth(
               ^^^^^^^^^^^^^^^^^^^^^^^^^^^^^^^
    ...<4 lines>...
    )
    ^
  File "C:\Users\HP\AppData\Local\Programs\Python\Python313\Lib\site-packages\httpx\_client.py", line 1657, in _send_handling_auth
    response = await self._send_handling_redirects(
               ^^^^^^^^^^^^^^^^^^^^^^^^^^^^^^^^^^^^
    ...<3 lines>...
    )
    ^
  File "C:\Users\HP\AppData\Local\Programs\Python\Python313\Lib\site-packages\httpx\_client.py", line 1694, in _send_handling_redirects
    response = await self._send_single_request(request)
               ^^^^^^^^^^^^^^^^^^^^^^^^^^^^^^^^^^^^^^^^
  File "C:\Users\HP\AppData\Local\Programs\Python\Python313\Lib\site-packages\httpx\_client.py", line 1730, in _send_single_request
    response = await transport.handle_async_request(request)
               ^^^^^^^^^^^^^^^^^^^^^^^^^^^^^^^^^^^^^^^^^^^^^
  File "C:\Users\HP\AppData\Local\Programs\Python\Python313\Lib\site-packages\httpx\_transports\default.py", line 393, in handle_async_request
    with map_httpcore_exceptions():
         ~~~~~~~~~~~~~~~~~~~~~~~^^
  File "C:\Users\HP\AppData\Local\Programs\Python\Python313\Lib\contextlib.py", line 162, in __exit__
    self.gen.throw(value)
    ~~~~~~~~~~~~~~^^^^^^^
  File "C:\Users\HP\AppData\Local\Programs\Python\Python313\Lib\site-packages\httpx\_transports\default.py", line 118, in map_httpcore_exceptions
    raise mapped_exc(message) from exc
httpx.ConnectError: [Errno 11001] getaddrinfo failed

The above exception was the direct cause of the following exception:

Traceback (most recent call last):
  File "C:\Users\HP\AppData\Local\Programs\Python\Python313\Lib\site-packages\telegram\ext\_utils\networkloop.py", line 115, in network_retry_loop
    if not await do_action():
           ^^^^^^^^^^^^^^^^^
  File "C:\Users\HP\AppData\Local\Programs\Python\Python313\Lib\site-packages\telegram\ext\_utils\networkloop.py", line 108, in do_action
    return action_cb_task.result()
           ~~~~~~~~~~~~~~~~~~~~~^^
  File "C:\Users\HP\AppData\Local\Programs\Python\Python313\Lib\site-packages\telegram\ext\_updater.py", line 335, in polling_action_cb
    updates = await self.bot.get_updates(
              ^^^^^^^^^^^^^^^^^^^^^^^^^^^
    ...<3 lines>...
    )
    ^
  File "C:\Users\HP\AppData\Local\Programs\Python\Python313\Lib\site-packages\telegram\ext\_extbot.py", line 669, in get_updates
    updates = await super().get_updates(
              ^^^^^^^^^^^^^^^^^^^^^^^^^^
    ...<9 lines>...
    )
    ^
  File "C:\Users\HP\AppData\Local\Programs\Python\Python313\Lib\site-packages\telegram\_bot.py", line 4601, in get_updates
    await self._post(
    ^^^^^^^^^^^^^^^^^
    ...<7 lines>...
    ),
    ^
  File "C:\Users\HP\AppData\Local\Programs\Python\Python313\Lib\site-packages\telegram\_bot.py", line 697, in _post
    return await self._do_post(
           ^^^^^^^^^^^^^^^^^^^^
    ...<6 lines>...
    )
    ^
  File "C:\Users\HP\AppData\Local\Programs\Python\Python313\Lib\site-packages\telegram\ext\_extbot.py", line 369, in _do_post
    return await super()._do_post(
           ^^^^^^^^^^^^^^^^^^^^^^^
    ...<6 lines>...
    )
    ^
  File "C:\Users\HP\AppData\Local\Programs\Python\Python313\Lib\site-packages\telegram\_bot.py", line 726, in _do_post
    result = await request.post(
             ^^^^^^^^^^^^^^^^^^^
    ...<6 lines>...
    )
    ^
  File "C:\Users\HP\AppData\Local\Programs\Python\Python313\Lib\site-packages\telegram\request\_baserequest.py", line 197, in post
    result = await self._request_wrapper(
             ^^^^^^^^^^^^^^^^^^^^^^^^^^^^
    ...<7 lines>...
    )
    ^
  File "C:\Users\HP\AppData\Local\Programs\Python\Python313\Lib\site-packages\telegram\request\_baserequest.py", line 304, in _request_wrapper
    code, payload = await self.do_request(
                    ^^^^^^^^^^^^^^^^^^^^^^
    ...<7 lines>...
    )
    ^
  File "C:\Users\HP\AppData\Local\Programs\Python\Python313\Lib\site-packages\telegram\request\_httpxrequest.py", line 297, in do_request
    raise NetworkError(f"httpx.{err.__class__.__name__}: {err}") from err
telegram.error.NetworkError: httpx.ConnectError: [Errno 11001] getaddrinfo failed
